/* An Exception can be generated by 1 method and could be caught by another*/

package exception_handling_examples;

class Exception_Test2 {

	static void method_gen_exception() {
		int nums[] = new int[4];

		System.out.println("Before exception is generated");
		nums[7] = 9; // exception is generated.
		System.out.println("This wont print");
	}

}

public class Exception_Demo2 {

	public static void main(String args[]) {

		try {
			// Calling the method from another class which will generate the array out of
			// bound exception
			Exception_Test2.method_gen_exception();
		} catch (ArrayIndexOutOfBoundsException exp1) {  //Catching the exception caused by another method.
			System.out.println("Index array is out of bounds, check the array assignment carefully!");
		}
		System.out.println("After the method is called");

	}

}
